Workbook

Sheet Dashboard
A1: PRACTICAL INCOME INVESTING- Trading Journal
A2: TOTAL P&L | F2: TOTAL COLLATERAL | K2: OVERALL ROC | P2: TOTAL WINS | U2: TOTAL TRADES
A3: =IFERROR(SUM('CC&CSP'!P5:'CC&CSP'!P304),0)+IFERROR(SUM('Call & Puts'!P5:'Call & Puts'!P304),0)+IFERROR(SUM('Credit Spreads'!S5:'Credit Spreads'!S304),0)+IFERROR(SUM('Buy-Writes'!S5:'Buy-Writes'!S304),0)+IFERROR(SUMIF(Stocks!R5:'Stocks'!R304,"Closed",Stocks!P5:'Stocks'!P304),0) -> 0 | F3: =IFERROR(SUM('CC&CSP'!O5:'CC&CSP'!O304),0)+IFERROR(SUM('Call & Puts'!O5:'Call & Puts'!O304),0)+IFERROR(SUM('Credit Spreads'!R5:'Credit Spreads'!R304),0)+IFERROR(SUM('Buy-Writes'!P5:'Buy-Writes'!P304),0) -> 0 | K3: =IFERROR(A5/F5,0) -> 0 | P3: =IFERROR(COUNTIF('CC&CSP'!P5:'CC&CSP'!P304,">0"),0)+IFERROR(COUNTIF('Call & Puts'!P5:'Call & Puts'!P304,">0"),0)+IFERROR(COUNTIF('Credit Spreads'!S5:'Credit Spreads'!S304,">0"),0)+IFERROR(COUNTIF('Buy-Writes'!S5:'Buy-Writes'!S304,">0"),0) -> 0 | U3: =IFERROR(COUNTA('CC&CSP'!A5:'CC&CSP'!A304),0)+IFERROR(COUNTA('Call & Puts'!A5:'Call & Puts'!A304),0)+IFERROR(COUNTA('Credit Spreads'!A5:'Credit Spreads'!A304),0)+IFERROR(COUNTA('Buy-Writes'!B5:'Buy-Writes'!B304),0) -> 0
A4: STRATEGY PERFORMANCE
A5: =IFERROR(SUM('CC&CSP'!P5:'CC&CSP'!P304),0)+IFERROR(SUM('Call & Puts'!P5:'Call & Puts'!P304),0)+IFERROR(SUM('Credit Spreads'!S5:'Credit Spreads'!S304),0)+IFERROR(SUM('Buy-Writes'!S5:'Buy-Writes'!S304),0)+IFERROR(SUMIF(Stocks!R5:'Stocks'!R304,"Closed",Stocks!P5:'Stocks'!P304),0) -> 0 | F5: =IFERROR(SUM('CC&CSP'!O5:'CC&CSP'!O304),0)+IFERROR(SUM('Call & Puts'!O5:'Call & Puts'!O304),0)+IFERROR(SUM('Credit Spreads'!R5:'Credit Spreads'!R304),0)+IFERROR(SUM('Buy-Writes'!P5:'Buy-Writes'!P304),0) -> 0
A6: STRATEGY | D6: TOTAL P&L | G6: WINS | I6: LOSSES | K6: WIN RATE | M6: AVG WIN | O6: AVG LOSS | Q6: COLLATERAL | T6: ROC % | V6: BEST TRADE | Y6: WORST TRADE
A7: CC & CSP | D7: =IFERROR(SUM('CC&CSP'!P5:'CC&CSP'!P304),0) -> 0 | G7: =IFERROR(COUNTIF('CC&CSP'!P5:'CC&CSP'!P304,">0"),0) -> 0 | I7: =IFERROR(COUNTIF('CC&CSP'!P5:'CC&CSP'!P304,"<0"),0) -> 0 | K7: =IFERROR(G7/(G7+I7),0) -> 0 | M7: =IFERROR(AVERAGEIF('CC&CSP'!P5:'CC&CSP'!P304,">0"),0) -> 0 | O7: =IFERROR(AVERAGEIF('CC&CSP'!P5:'CC&CSP'!P304,"<0"),0) -> 0 | Q7: =IFERROR(SUM('CC&CSP'!O5:'CC&CSP'!O304),0) -> 0 | T7: =IFERROR(D7/Q7,0) -> 0 | V7: =IFERROR(MAX('CC&CSP'!P5:'CC&CSP'!P304),0) -> 0 | Y7: =IFERROR(MIN('CC&CSP'!P5:'CC&CSP'!P304),0) -> 0
A8: LEAPS & Swings | D8: =IFERROR(SUM('Call & Puts'!P5:'Call & Puts'!P304),0) -> 0 | G8: =IFERROR(COUNTIF('Call & Puts'!P5:'Call & Puts'!P304,">0"),0) -> 0 | I8: =IFERROR(COUNTIF('Call & Puts'!P5:'Call & Puts'!P304,"<0"),0) -> 0 | K8: =IFERROR(G8/(G8+I8),0) -> 0 | M8: =IFERROR(AVERAGEIF('Call & Puts'!P5:'Call & Puts'!P304,">0"),0) -> 0 | O8: =IFERROR(AVERAGEIF('Call & Puts'!P5:'Call & Puts'!P304,"<0"),0) -> 0 | Q8: =IFERROR(SUM('Call & Puts'!O5:'Call & Puts'!O304),0) -> 0 | T8: =IFERROR(D8/Q8,0) -> 0 | V8: =IFERROR(MAX('Call & Puts'!P5:'Call & Puts'!P304),0) -> 0 | Y8: =IFERROR(MIN('Call & Puts'!P5:'Call & Puts'!P304),0) -> 0
A9: Credit Spreads | D9: =IFERROR(SUM('Credit Spreads'!S5:'Credit Spreads'!S304),0) -> 0 | G9: =IFERROR(COUNTIF('Credit Spreads'!S5:'Credit Spreads'!S304,">0"),0) -> 0 | I9: =IFERROR(COUNTIF('Credit Spreads'!S5:'Credit Spreads'!S304,"<0"),0) -> 0 | K9: =IFERROR(G9/(G9+I9),0) -> 0 | M9: =IFERROR(AVERAGEIF('Credit Spreads'!S5:'Credit Spreads'!S304,">0"),0) -> 0 | O9: =IFERROR(AVERAGEIF('Credit Spreads'!S5:'Credit Spreads'!S304,"<0"),0) -> 0 | Q9: =IFERROR(SUM('Credit Spreads'!R5:'Credit Spreads'!R304),0) -> 0 | T9: =IFERROR(D9/Q9,0) -> 0 | V9: =IFERROR(MAX('Credit Spreads'!S5:'Credit Spreads'!S304),0) -> 0 | Y9: =IFERROR(MIN('Credit Spreads'!S5:'Credit Spreads'!S304),0) -> 0
A10: Buy-Writes | D10: =IFERROR(SUM('Buy-Writes'!S5:'Buy-Writes'!S304),0) -> 0 | G10: =IFERROR(COUNTIF('Buy-Writes'!S5:'Buy-Writes'!S304,">0"),0) -> 0 | I10: =IFERROR(COUNTIF('Buy-Writes'!S5:'Buy-Writes'!S304,"<0"),0) -> 0 | K10: =IFERROR(G10/(G10+I10),0) -> 0 | M10: =IFERROR(AVERAGEIF('Buy-Writes'!S5:'Buy-Writes'!S304,">0"),0) -> 0 | O10: =IFERROR(AVERAGEIF('Buy-Writes'!S5:'Buy-Writes'!S304,"<0"),0) -> 0 | Q10: =IFERROR(SUM('Buy-Writes'!P5:'Buy-Writes'!P304),0) -> 0 | T10: =IFERROR(D10/Q10,0) -> 0 | V10: =IFERROR(MAX('Buy-Writes'!S5:'Buy-Writes'!S304),0) -> 0 | Y10: =IFERROR(MIN('Buy-Writes'!S5:'Buy-Writes'!S304),0) -> 0
A11: Stocks | D11: =IFERROR(SUM(Stocks!P5:'Stocks'!P304),0) -> 0 | G11: =IFERROR(COUNTIF(Stocks!P5:'Stocks'!P304,">0"),0) -> 0 | I11: =IFERROR(COUNTIF(Stocks!P5:'Stocks'!P304,"<0"),0) -> 0 | K11: =IFERROR(G11/(G11+I11),0) -> 0 | M11: =IFERROR(AVERAGEIF(Stocks!P5:'Stocks'!P304,">0"),0) -> 0 | O11: =IFERROR(AVERAGEIF(Stocks!P5:'Stocks'!P304,"<0"),0) -> 0 | Q11: 0 | T11: =IFERROR(D11/Q11,0) -> 0 | V11: =IFERROR(MAX(Stocks!P5:'Stocks'!P304),0) -> 0 | Y11: =IFERROR(MIN(Stocks!P5:'Stocks'!P304),0) -> 0
A13: MONTHLY BREAKDOWN
A14: MONTH | C14: CC & CSP | G14: LEAPS & SWINGS | K14: CREDIT SPREADS | O14: BUY-WRITES | S14: STOCKS | W14: TOTAL
A15: Jan 2026 | C15: =IFERROR(SUMPRODUCT((MONTH('CC&CSP'!E5:'CC&CSP'!E304)=1)*(YEAR('CC&CSP'!E5:'CC&CSP'!E304)=2026)*('CC&CSP'!P5:'CC&CSP'!P304)),0) -> 0 | G15: =IFERROR(SUMPRODUCT((MONTH('Call & Puts'!E5:'Call & Puts'!E304)=1)*(YEAR('Call & Puts'!E5:'Call & Puts'!E304)=2026)*('Call & Puts'!P5:'Call & Puts'!P304)),0) -> 0 | K15: =IFERROR(SUMPRODUCT((MONTH('Credit Spreads'!E5:'Credit Spreads'!E304)=1)*(YEAR('Credit Spreads'!E5:'Credit Spreads'!E304)=2026)*('Credit Spreads'!S5:'Credit Spreads'!S304)),0) -> 0 | O15: =IFERROR(SUMPRODUCT((MONTH('Buy-Writes'!D5:'Buy-Writes'!D304)=1)*(YEAR('Buy-Writes'!D5:'Buy-Writes'!D304)=2026)*('Buy-Writes'!S5:'Buy-Writes'!S304)),0) -> 0 | S15: =IFERROR(SUMPRODUCT((MONTH(Stocks!M5:'Stocks'!M304)=1)*(YEAR(Stocks!M5:'Stocks'!M304)=2026)*(Stocks!P5:'Stocks'!P304)),0) -> 0 | W15: =IFERROR(C15+G15+K15+O15+S15,0) -> 0
A16: Feb 2026 | C16: =IFERROR(SUMPRODUCT((MONTH('CC&CSP'!E5:'CC&CSP'!E304)=2)*(YEAR('CC&CSP'!E5:'CC&CSP'!E304)=2026)*('CC&CSP'!P5:'CC&CSP'!P304)),0) -> 0 | G16: =IFERROR(SUMPRODUCT((MONTH('Call & Puts'!E5:'Call & Puts'!E304)=2)*(YEAR('Call & Puts'!E5:'Call & Puts'!E304)=2026)*('Call & Puts'!P5:'Call & Puts'!P304)),0) -> 0 | K16: =IFERROR(SUMPRODUCT((MONTH('Credit Spreads'!E5:'Credit Spreads'!E304)=2)*(YEAR('Credit Spreads'!E5:'Credit Spreads'!E304)=2026)*('Credit Spreads'!S5:'Credit Spreads'!S304)),0) -> 0 | O16: =IFERROR(SUMPRODUCT((MONTH('Buy-Writes'!D5:'Buy-Writes'!D304)=2)*(YEAR('Buy-Writes'!D5:'Buy-Writes'!D304)=2026)*('Buy-Writes'!S5:'Buy-Writes'!S304)),0) -> 0 | S16: =IFERROR(SUMPRODUCT((MONTH(Stocks!M5:'Stocks'!M304)=2)*(YEAR(Stocks!M5:'Stocks'!M304)=2026)*(Stocks!P5:'Stocks'!P304)),0) -> 0 | W16: =IFERROR(C16+G16+K16+O16+S16,0) -> 0
A17: Mar 2026 | C17: =IFERROR(SUMPRODUCT((MONTH('CC&CSP'!E5:'CC&CSP'!E304)=3)*(YEAR('CC&CSP'!E5:'CC&CSP'!E304)=2026)*('CC&CSP'!P5:'CC&CSP'!P304)),0) -> 0 | G17: =IFERROR(SUMPRODUCT((MONTH('Call & Puts'!E5:'Call & Puts'!E304)=3)*(YEAR('Call & Puts'!E5:'Call & Puts'!E304)=2026)*('Call & Puts'!P5:'Call & Puts'!P304)),0) -> 0 | K17: =IFERROR(SUMPRODUCT((MONTH('Credit Spreads'!E5:'Credit Spreads'!E304)=3)*(YEAR('Credit Spreads'!E5:'Credit Spreads'!E304)=2026)*('Credit Spreads'!S5:'Credit Spreads'!S304)),0) -> 0 | O17: =IFERROR(SUMPRODUCT((MONTH('Buy-Writes'!D5:'Buy-Writes'!D304)=3)*(YEAR('Buy-Writes'!D5:'Buy-Writes'!D304)=2026)*('Buy-Writes'!S5:'Buy-Writes'!S304)),0) -> 0 | S17: =IFERROR(SUMPRODUCT((MONTH(Stocks!M5:'Stocks'!M304)=3)*(YEAR(Stocks!M5:'Stocks'!M304)=2026)*(Stocks!P5:'Stocks'!P304)),0) -> 0 | W17: =IFERROR(C17+G17+K17+O17+S17,0) -> 0
A18: Apr 2026 | C18: =IFERROR(SUMPRODUCT((MONTH('CC&CSP'!E5:'CC&CSP'!E304)=4)*(YEAR('CC&CSP'!E5:'CC&CSP'!E304)=2026)*('CC&CSP'!P5:'CC&CSP'!P304)),0) -> 0 | G18: =IFERROR(SUMPRODUCT((MONTH('Call & Puts'!E5:'Call & Puts'!E304)=4)*(YEAR('Call & Puts'!E5:'Call & Puts'!E304)=2026)*('Call & Puts'!P5:'Call & Puts'!P304)),0) -> 0 | K18: =IFERROR(SUMPRODUCT((MONTH('Credit Spreads'!E5:'Credit Spreads'!E304)=4)*(YEAR('Credit Spreads'!E5:'Credit Spreads'!E304)=2026)*('Credit Spreads'!S5:'Credit Spreads'!S304)),0) -> 0 | O18: =IFERROR(SUMPRODUCT((MONTH('Buy-Writes'!D5:'Buy-Writes'!D304)=4)*(YEAR('Buy-Writes'!D5:'Buy-Writes'!D304)=2026)*('Buy-Writes'!S5:'Buy-Writes'!S304)),0) -> 0 | S18: =IFERROR(SUMPRODUCT((MONTH(Stocks!M5:'Stocks'!M304)=4)*(YEAR(Stocks!M5:'Stocks'!M304)=2026)*(Stocks!P5:'Stocks'!P304)),0) -> 0 | W18: =IFERROR(C18+G18+K18+O18+S18,0) -> 0
A19: May 2026 | C19: =IFERROR(SUMPRODUCT((MONTH('CC&CSP'!E5:'CC&CSP'!E304)=5)*(YEAR('CC&CSP'!E5:'CC&CSP'!E304)=2026)*('CC&CSP'!P5:'CC&CSP'!P304)),0) -> 0 | G19: =IFERROR(SUMPRODUCT((MONTH('Call & Puts'!E5:'Call & Puts'!E304)=5)*(YEAR('Call & Puts'!E5:'Call & Puts'!E304)=2026)*('Call & Puts'!P5:'Call & Puts'!P304)),0) -> 0 | K19: =IFERROR(SUMPRODUCT((MONTH('Credit Spreads'!E5:'Credit Spreads'!E304)=5)*(YEAR('Credit Spreads'!E5:'Credit Spreads'!E304)=2026)*('Credit Spreads'!S5:'Credit Spreads'!S304)),0) -> 0 | O19: =IFERROR(SUMPRODUCT((MONTH('Buy-Writes'!D5:'Buy-Writes'!D304)=5)*(YEAR('Buy-Writes'!D5:'Buy-Writes'!D304)=2026)*('Buy-Writes'!S5:'Buy-Writes'!S304)),0) -> 0 | S19: =IFERROR(SUMPRODUCT((MONTH(Stocks!M5:'Stocks'!M304)=5)*(YEAR(Stocks!M5:'Stocks'!M304)=2026)*(Stocks!P5:'Stocks'!P304)),0) -> 0 | W19: =IFERROR(C19+G19+K19+O19+S19,0) -> 0
A20: Jun 2026 | C20: =IFERROR(SUMPRODUCT((MONTH('CC&CSP'!E5:'CC&CSP'!E304)=6)*(YEAR('CC&CSP'!E5:'CC&CSP'!E304)=2026)*('CC&CSP'!P5:'CC&CSP'!P304)),0) -> 0 | G20: =IFERROR(SUMPRODUCT((MONTH('Call & Puts'!E5:'Call & Puts'!E304)=6)*(YEAR('Call & Puts'!E5:'Call & Puts'!E304)=2026)*('Call & Puts'!P5:'Call & Puts'!P304)),0) -> 0 | K20: =IFERROR(SUMPRODUCT((MONTH('Credit Spreads'!E5:'Credit Spreads'!E304)=6)*(YEAR('Credit Spreads'!E5:'Credit Spreads'!E304)=2026)*('Credit Spreads'!S5:'Credit Spreads'!S304)),0) -> 0 | O20: =IFERROR(SUMPRODUCT((MONTH('Buy-Writes'!D5:'Buy-Writes'!D304)=6)*(YEAR('Buy-Writes'!D5:'Buy-Writes'!D304)=2026)*('Buy-Writes'!S5:'Buy-Writes'!S304)),0) -> 0 | S20: =IFERROR(SUMPRODUCT((MONTH(Stocks!M5:'Stocks'!M304)=6)*(YEAR(Stocks!M5:'Stocks'!M304)=2026)*(Stocks!P5:'Stocks'!P304)),0) -> 0 | W20: =IFERROR(C20+G20+K20+O20+S20,0) -> 0
A21: Jul 2026 | C21: =IFERROR(SUMPRODUCT((MONTH('CC&CSP'!E5:'CC&CSP'!E304)=7)*(YEAR('CC&CSP'!E5:'CC&CSP'!E304)=2026)*('CC&CSP'!P5:'CC&CSP'!P304)),0) -> 0 | G21: =IFERROR(SUMPRODUCT((MONTH('Call & Puts'!E5:'Call & Puts'!E304)=7)*(YEAR('Call & Puts'!E5:'Call & Puts'!E304)=2026)*('Call & Puts'!P5:'Call & Puts'!P304)),0) -> 0 | K21: =IFERROR(SUMPRODUCT((MONTH('Credit Spreads'!E5:'Credit Spreads'!E304)=7)*(YEAR('Credit Spreads'!E5:'Credit Spreads'!E304)=2026)*('Credit Spreads'!S5:'Credit Spreads'!S304)),0) -> 0 | O21: =IFERROR(SUMPRODUCT((MONTH('Buy-Writes'!D5:'Buy-Writes'!D304)=7)*(YEAR('Buy-Writes'!D5:'Buy-Writes'!D304)=2026)*('Buy-Writes'!S5:'Buy-Writes'!S304)),0) -> 0 | S21: =IFERROR(SUMPRODUCT((MONTH(Stocks!M5:'Stocks'!M304)=7)*(YEAR(Stocks!M5:'Stocks'!M304)=2026)*(Stocks!P5:'Stocks'!P304)),0) -> 0 | W21: =IFERROR(C21+G21+K21+O21+S21,0) -> 0
A22: Aug 2026 | C22: =IFERROR(SUMPRODUCT((MONTH('CC&CSP'!E5:'CC&CSP'!E304)=8)*(YEAR('CC&CSP'!E5:'CC&CSP'!E304)=2026)*('CC&CSP'!P5:'CC&CSP'!P304)),0) -> 0 | G22: =IFERROR(SUMPRODUCT((MONTH('Call & Puts'!E5:'Call & Puts'!E304)=8)*(YEAR('Call & Puts'!E5:'Call & Puts'!E304)=2026)*('Call & Puts'!P5:'Call & Puts'!P304)),0) -> 0 | K22: =IFERROR(SUMPRODUCT((MONTH('Credit Spreads'!E5:'Credit Spreads'!E304)=8)*(YEAR('Credit Spreads'!E5:'Credit Spreads'!E304)=2026)*('Credit Spreads'!S5:'Credit Spreads'!S304)),0) -> 0 | O22: =IFERROR(SUMPRODUCT((MONTH('Buy-Writes'!D5:'Buy-Writes'!D304)=8)*(YEAR('Buy-Writes'!D5:'Buy-Writes'!D304)=2026)*('Buy-Writes'!S5:'Buy-Writes'!S304)),0) -> 0 | S22: =IFERROR(SUMPRODUCT((MONTH(Stocks!M5:'Stocks'!M304)=8)*(YEAR(Stocks!M5:'Stocks'!M304)=2026)*(Stocks!P5:'Stocks'!P304)),0) -> 0 | W22: =IFERROR(C22+G22+K22+O22+S22,0) -> 0
A23: Sep 2026 | C23: =IFERROR(SUMPRODUCT((MONTH('CC&CSP'!E5:'CC&CSP'!E304)=9)*(YEAR('CC&CSP'!E5:'CC&CSP'!E304)=2026)*('CC&CSP'!P5:'CC&CSP'!P304)),0) -> 0 | G23: =IFERROR(SUMPRODUCT((MONTH('Call & Puts'!E5:'Call & Puts'!E304)=9)*(YEAR('Call & Puts'!E5:'Call & Puts'!E304)=2026)*('Call & Puts'!P5:'Call & Puts'!P304)),0) -> 0 | K23: =IFERROR(SUMPRODUCT((MONTH('Credit Spreads'!E5:'Credit Spreads'!E304)=9)*(YEAR('Credit Spreads'!E5:'Credit Spreads'!E304)=2026)*('Credit Spreads'!S5:'Credit Spreads'!S304)),0) -> 0 | O23: =IFERROR(SUMPRODUCT((MONTH('Buy-Writes'!D5:'Buy-Writes'!D304)=9)*(YEAR('Buy-Writes'!D5:'Buy-Writes'!D304)=2026)*('Buy-Writes'!S5:'Buy-Writes'!S304)),0) -> 0 | S23: =IFERROR(SUMPRODUCT((MONTH(Stocks!M5:'Stocks'!M304)=9)*(YEAR(Stocks!M5:'Stocks'!M304)=2026)*(Stocks!P5:'Stocks'!P304)),0) -> 0 | W23: =IFERROR(C23+G23+K23+O23+S23,0) -> 0
A24: Oct 2026 | C24: =IFERROR(SUMPRODUCT((MONTH('CC&CSP'!E5:'CC&CSP'!E304)=10)*(YEAR('CC&CSP'!E5:'CC&CSP'!E304)=2026)*('CC&CSP'!P5:'CC&CSP'!P304)),0) -> 0 | G24: =IFERROR(SUMPRODUCT((MONTH('Call & Puts'!E5:'Call & Puts'!E304)=10)*(YEAR('Call & Puts'!E5:'Call & Puts'!E304)=2026)*('Call & Puts'!P5:'Call & Puts'!P304)),0) -> 0 | K24: =IFERROR(SUMPRODUCT((MONTH('Credit Spreads'!E5:'Credit Spreads'!E304)=10)*(YEAR('Credit Spreads'!E5:'Credit Spreads'!E304)=2026)*('Credit Spreads'!S5:'Credit Spreads'!S304)),0) -> 0 | O24: =IFERROR(SUMPRODUCT((MONTH('Buy-Writes'!D5:'Buy-Writes'!D304)=10)*(YEAR('Buy-Writes'!D5:'Buy-Writes'!D304)=2026)*('Buy-Writes'!S5:'Buy-Writes'!S304)),0) -> 0 | S24: =IFERROR(SUMPRODUCT((MONTH(Stocks!M5:'Stocks'!M304)=10)*(YEAR(Stocks!M5:'Stocks'!M304)=2026)*(Stocks!P5:'Stocks'!P304)),0) -> 0 | W24: =IFERROR(C24+G24+K24+O24+S24,0) -> 0
A25: Nov 2026 | C25: =IFERROR(SUMPRODUCT((MONTH('CC&CSP'!E5:'CC&CSP'!E304)=11)*(YEAR('CC&CSP'!E5:'CC&CSP'!E304)=2026)*('CC&CSP'!P5:'CC&CSP'!P304)),0) -> 0 | G25: =IFERROR(SUMPRODUCT((MONTH('Call & Puts'!E5:'Call & Puts'!E304)=11)*(YEAR('Call & Puts'!E5:'Call & Puts'!E304)=2026)*('Call & Puts'!P5:'Call & Puts'!P304)),0) -> 0 | K25: =IFERROR(SUMPRODUCT((MONTH('Credit Spreads'!E5:'Credit Spreads'!E304)=11)*(YEAR('Credit Spreads'!E5:'Credit Spreads'!E304)=2026)*('Credit Spreads'!S5:'Credit Spreads'!S304)),0) -> 0 | O25: =IFERROR(SUMPRODUCT((MONTH('Buy-Writes'!D5:'Buy-Writes'!D304)=11)*(YEAR('Buy-Writes'!D5:'Buy-Writes'!D304)=2026)*('Buy-Writes'!S5:'Buy-Writes'!S304)),0) -> 0 | S25: =IFERROR(SUMPRODUCT((MONTH(Stocks!M5:'Stocks'!M304)=11)*(YEAR(Stocks!M5:'Stocks'!M304)=2026)*(Stocks!P5:'Stocks'!P304)),0) -> 0 | W25: =IFERROR(C25+G25+K25+O25+S25,0) -> 0
A26: Dec 2026 | C26: =IFERROR(SUMPRODUCT((MONTH('CC&CSP'!E5:'CC&CSP'!E304)=12)*(YEAR('CC&CSP'!E5:'CC&CSP'!E304)=2026)*('CC&CSP'!P5:'CC&CSP'!P304)),0) -> 0 | G26: =IFERROR(SUMPRODUCT((MONTH('Call & Puts'!E5:'Call & Puts'!E304)=12)*(YEAR('Call & Puts'!E5:'Call & Puts'!E304)=2026)*('Call & Puts'!P5:'Call & Puts'!P304)),0) -> 0 | K26: =IFERROR(SUMPRODUCT((MONTH('Credit Spreads'!E5:'Credit Spreads'!E304)=12)*(YEAR('Credit Spreads'!E5:'Credit Spreads'!E304)=2026)*('Credit Spreads'!S5:'Credit Spreads'!S304)),0) -> 0 | O26: =IFERROR(SUMPRODUCT((MONTH('Buy-Writes'!D5:'Buy-Writes'!D304)=12)*(YEAR('Buy-Writes'!D5:'Buy-Writes'!D304)=2026)*('Buy-Writes'!S5:'Buy-Writes'!S304)),0) -> 0 | S26: =IFERROR(SUMPRODUCT((MONTH(Stocks!M5:'Stocks'!M304)=12)*(YEAR(Stocks!M5:'Stocks'!M304)=2026)*(Stocks!P5:'Stocks'!P304)),0) -> 0 | W26: =IFERROR(C26+G26+K26+O26+S26,0) -> 0

Sheet CC&CSP
A1: Practical Income Investing - Covered Calls & Cash Secured Puts
A2: TOTAL PROFIT | E2: =SUM(P5:P304) -> 0 | J2: COLLATERAL USED | N2: =IFERROR(SUMIF(E5:E304,"<>",O5:O304),0) -> 0 | P2: TOTAL ROC | S2: =IFERROR(E2/N2,0) -> 0 | V2: Locked Cells | W2: Manually Enter
A3: WINS | C3: =COUNTIF(P5:P304,">0") -> 0 | D3: LOSSES | F3: =COUNTIF(P5:P304,"<0") -> 0 | H3: WIN RATE | K3: =IFERROR(C3/(C3+F3),0) -> 0 | M3: AVG WIN | O3: =IFERROR(AVERAGEIF(P5:P304,">0"),0) -> 0 | Q3: AVG LOSS | S3: =IFERROR(AVERAGEIF(P5:P304,"<0"),0) -> 0 | V3: Cell Use Guide
A4: TYPE | B4: STRATEGY | C4: OPEN DATE | D4: EXP DATE | E4: CLOSE DATE | F4: TICKER | G4: BROKERAGE | H4: TODAY'S PRICE | I4: STRIKE $ | J4: BREACH ALERT | K4: QTY | L4: PREMIUM $ | M4: CLOSE $ | N4: CC COLLATERAL | O4: COLLATERAL $ | P4: P / L | Q4: #DAYS | R4: PROFIT PER DAY | S4: RETURN ON CAPITAL | T4: MONTHLY RETURN % | U4: ANNUAL RETURN % | V4: NOTES
J5: =IF(OR(A5="",E5<>""),"",IFERROR(H5-I5,"")) | P5: =IF(A5="","",IF(A5="Sell",IF(M5="","", (L5-M5)*K5*100),IF(A5="Assigned",IF(L5="","",L5*K5*100),IF(A5="Buy",IF(M5="","",(M5-L5)*K5*100),"")))) | Q5: =IF(E5="","",IF(E5-C5<1,1,E5-C5)) | R5: =IFERROR(IF(P5="","",P5/Q5),"") | S5: =IF(E5="","",IFERROR(IF(N5="",P5/O5,P5/N5),"")) | T5: =IFERROR(IF(S5="","",S5/Q5*365/12),"") | U5: =IFERROR(IF(S5="","",S5/Q5*365),"")
J6: =IF(OR(A6="",E6<>""),"",IFERROR(H6-I6,"")) | P6: =IF(A6="","",IF(A6="Sell",IF(M6="","", (L6-M6)*K6*100),IF(A6="Assigned",IF(L6="","",L6*K6*100),IF(A6="Buy",IF(M6="","",(M6-L6)*K6*100),"")))) | Q6: =IF(E6="","",IF(E6-C6<1,1,E6-C6)) | R6: =IFERROR(IF(P6="","",P6/Q6),"") | S6: =IF(E6="","",IFERROR(IF(N6="",P6/O6,P6/N6),"")) | T6: =IFERROR(IF(S6="","",S6/Q6*365/12),"") | U6: =IFERROR(IF(S6="","",S6/Q6*365),"")
J7: =IF(OR(A7="",E7<>""),"",IFERROR(H7-I7,"")) | P7: =IF(A7="","",IF(A7="Sell",IF(M7="","", (L7-M7)*K7*100),IF(A7="Assigned",IF(L7="","",L7*K7*100),IF(A7="Buy",IF(M7="","",(M7-L7)*K7*100),"")))) | Q7: =IF(E7="","",IF(E7-C7<1,1,E7-C7)) | R7: =IFERROR(IF(P7="","",P7/Q7),"") | S7: =IF(E7="","",IFERROR(IF(N7="",P7/O7,P7/N7),"")) | T7: =IFERROR(IF(S7="","",S7/Q7*365/12),"") | U7: =IFERROR(IF(S7="","",S7/Q7*365),"")
H8: =IFERROR(__xludf.DUMMYFUNCTION("IF(F8="""","""",IFERROR(GOOGLEFINANCE(UPPER(F8),""price""),""""))"),"") | J8: =IF(OR(A8="",E8<>""),"",IFERROR(H8-I8,"")) | P8: =IF(A8="","",IF(A8="Sell",IF(M8="","", (L8-M8)*K8*100),IF(A8="Assigned",IF(L8="","",L8*K8*100),IF(A8="Buy",IF(M8="","",(M8-L8)*K8*100),"")))) | Q8: =IF(E8="","",IF(E8-C8<1,1,E8-C8)) | R8: =IFERROR(IF(P8="","",P8/Q8),"") | S8: =IF(E8="","",IFERROR(IF(N8="",P8/O8,P8/N8),"")) | T8: =IFERROR(IF(S8="","",S8/Q8*365/12),"") | U8: =IFERROR(IF(S8="","",S8/Q8*365),"")
H9: =IFERROR(__xludf.DUMMYFUNCTION("IF(F9="""","""",IFERROR(GOOGLEFINANCE(UPPER(F9),""price""),""""))"),"") | J9: =IF(OR(A9="",E9<>""),"",IFERROR(H9-I9,"")) | P9: =IF(A9="","",IF(A9="Sell",IF(M9="","", (L9-M9)*K9*100),IF(A9="Assigned",IF(L9="","",L9*K9*100),IF(A9="Buy",IF(M9="","",(M9-L9)*K9*100),"")))) | Q9: =IF(E9="","",IF(E9-C9<1,1,E9-C9)) | R9: =IFERROR(IF(P9="","",P9/Q9),"") | S9: =IF(E9="","",IFERROR(IF(N9="",P9/O9,P9/N9),"")) | T9: =IFERROR(IF(S9="","",S9/Q9*365/12),"") | U9: =IFERROR(IF(S9="","",S9/Q9*365),"")
H10: =IFERROR(__xludf.DUMMYFUNCTION("IF(F10="""","""",IFERROR(GOOGLEFINANCE(UPPER(F10),""price""),""""))"),"") | J10: =IF(OR(A10="",E10<>""),"",IFERROR(H10-I10,"")) | P10: =IF(A10="","",IF(A10="Sell",IF(M10="","", (L10-M10)*K10*100),IF(A10="Assigned",IF(L10="","",L10*K10*100),IF(A10="Buy",IF(M10="","",(M10-L10)*K10*100),"")))) | Q10: =IF(E10="","",IF(E10-C10<1,1,E10-C10)) | R10: =IFERROR(IF(P10="","",P10/Q10),"") | S10: =IF(E10="","",IFERROR(IF(N10="",P10/O10,P10/N10),"")) | T10: =IFERROR(IF(S10="","",S10/Q10*365/12),"") | U10: =IFERROR(IF(S10="","",S10/Q10*365),"")
H11: =IFERROR(__xludf.DUMMYFUNCTION("IF(F11="""","""",IFERROR(GOOGLEFINANCE(UPPER(F11),""price""),""""))"),"") | J11: =IF(OR(A11="",E11<>""),"",IFERROR(H11-I11,"")) | P11: =IF(A11="","",IF(A11="Sell",IF(M11="","", (L11-M11)*K11*100),IF(A11="Assigned",IF(L11="","",L11*K11*100),IF(A11="Buy",IF(M11="","",(M11-L11)*K11*100),"")))) | Q11: =IF(E11="","",IF(E11-C11<1,1,E11-C11)) | R11: =IFERROR(IF(P11="","",P11/Q11),"") | S11: =IF(E11="","",IFERROR(IF(N11="",P11/O11,P11/N11),"")) | T11: =IFERROR(IF(S11="","",S11/Q11*365/12),"") | U11: =IFERROR(IF(S11="","",S11/Q11*365),"")
H12: =IFERROR(__xludf.DUMMYFUNCTION("IF(F12="""","""",IFERROR(GOOGLEFINANCE(UPPER(F12),""price""),""""))"),"") | J12: =IF(OR(A12="",E12<>""),"",IFERROR(H12-I12,"")) | P12: =IF(A12="","",IF(A12="Sell",IF(M12="","", (L12-M12)*K12*100),IF(A12="Assigned",IF(L12="","",L12*K12*100),IF(A12="Buy",IF(M12="","",(M12-L12)*K12*100),"")))) | Q12: =IF(E12="","",IF(E12-C12<1,1,E12-C12)) | R12: =IFERROR(IF(P12="","",P12/Q12),"") | S12: =IF(E12="","",IFERROR(IF(N12="",P12/O12,P12/N12),"")) | T12: =IFERROR(IF(S12="","",S12/Q12*365/12),"") | U12: =IFERROR(IF(S12="","",S12/Q12*365),"")
H13: =IFERROR(__xludf.DUMMYFUNCTION("IF(F13="""","""",IFERROR(GOOGLEFINANCE(UPPER(F13),""price""),""""))"),"") | J13: =IF(OR(A13="",E13<>""),"",IFERROR(H13-I13,"")) | P13: =IF(A13="","",IF(A13="Sell",IF(M13="","", (L13-M13)*K13*100),IF(A13="Assigned",IF(L13="","",L13*K13*100),IF(A13="Buy",IF(M13="","",(M13-L13)*K13*100),"")))) | Q13: =IF(E13="","",IF(E13-C13<1,1,E13-C13)) | R13: =IFERROR(IF(P13="","",P13/Q13),"") | S13: =IF(E13="","",IFERROR(IF(N13="",P13/O13,P13/N13),"")) | T13: =IFERROR(IF(S13="","",S13/Q13*365/12),"") | U13: =IFERROR(IF(S13="","",S13/Q13*365),"")
H14: =IFERROR(__xludf.DUMMYFUNCTION("IF(F14="""","""",IFERROR(GOOGLEFINANCE(UPPER(F14),""price""),""""))"),"") | J14: =IF(OR(A14="",E14<>""),"",IFERROR(H14-I14,"")) | P14: =IF(A14="","",IF(A14="Sell",IF(M14="","", (L14-M14)*K14*100),IF(A14="Assigned",IF(L14="","",L14*K14*100),IF(A14="Buy",IF(M14="","",(M14-L14)*K14*100),"")))) | Q14: =IF(E14="","",IF(E14-C14<1,1,E14-C14)) | R14: =IFERROR(IF(P14="","",P14/Q14),"") | S14: =IF(E14="","",IFERROR(IF(N14="",P14/O14,P14/N14),"")) | T14: =IFERROR(IF(S14="","",S14/Q14*365/12),"") | U14: =IFERROR(IF(S14="","",S14/Q14*365),"")
H15: =IFERROR(__xludf.DUMMYFUNCTION("IF(F15="""","""",IFERROR(GOOGLEFINANCE(UPPER(F15),""price""),""""))"),"") | J15: =IF(OR(A15="",E15<>""),"",IFERROR(H15-I15,"")) | P15: =IF(A15="","",IF(A15="Sell",IF(M15="","", (L15-M15)*K15*100),IF(A15="Assigned",IF(L15="","",L15*K15*100),IF(A15="Buy",IF(M15="","",(M15-L15)*K15*100),"")))) | Q15: =IF(E15="","",IF(E15-C15<1,1,E15-C15)) | R15: =IFERROR(IF(P15="","",P15/Q15),"") | S15: =IF(E15="","",IFERROR(IF(N15="",P15/O15,P15/N15),"")) | T15: =IFERROR(IF(S15="","",S15/Q15*365/12),"") | U15: =IFERROR(IF(S15="","",S15/Q15*365),"")
H16: =IFERROR(__xludf.DUMMYFUNCTION("IF(F16="""","""",IFERROR(GOOGLEFINANCE(UPPER(F16),""price""),""""))"),"") | J16: =IF(OR(A16="",E16<>""),"",IFERROR(H16-I16,"")) | P16: =IF(A16="","",IF(A16="Sell",IF(M16="","", (L16-M16)*K16*100),IF(A16="Assigned",IF(L16="","",L16*K16*100),IF(A16="Buy",IF(M16="","",(M16-L16)*K16*100),"")))) | Q16: =IF(E16="","",IF(E16-C16<1,1,E16-C16)) | R16: =IFERROR(IF(P16="","",P16/Q16),"") | S16: =IF(E16="","",IFERROR(IF(N16="",P16/O16,P16/N16),"")) | T16: =IFERROR(IF(S16="","",S16/Q16*365/12),"") | U16: =IFERROR(IF(S16="","",S16/Q16*365),"")
H17: =IFERROR(__xludf.DUMMYFUNCTION("IF(F17="""","""",IFERROR(GOOGLEFINANCE(UPPER(F17),""price""),""""))"),"") | J17: =IF(OR(A17="",E17<>""),"",IFERROR(H17-I17,"")) | P17: =IF(A17="","",IF(A17="Sell",IF(M17="","", (L17-M17)*K17*100),IF(A17="Assigned",IF(L17="","",L17*K17*100),IF(A17="Buy",IF(M17="","",(M17-L17)*K17*100),"")))) | Q17: =IF(E17="","",IF(E17-C17<1,1,E17-C17)) | R17: =IFERROR(IF(P17="","",P17/Q17),"") | S17: =IF(E17="","",IFERROR(IF(N17="",P17/O17,P17/N17),"")) | T17: =IFERROR(IF(S17="","",S17/Q17*365/12),"") | U17: =IFERROR(IF(S17="","",S17/Q17*365),"")
H18: =IFERROR(__xludf.DUMMYFUNCTION("IF(F18="""","""",IFERROR(GOOGLEFINANCE(UPPER(F18),""price""),""""))"),"") | J18: =IF(OR(A18="",E18<>""),"",IFERROR(H18-I18,"")) | P18: =IF(A18="","",IF(A18="Sell",IF(M18="","", (L18-M18)*K18*100),IF(A18="Assigned",IF(L18="","",L18*K18*100),IF(A18="Buy",IF(M18="","",(M18-L18)*K18*100),"")))) | Q18: =IF(E18="","",IF(E18-C18<1,1,E18-C18)) | R18: =IFERROR(IF(P18="","",P18/Q18),"") | S18: =IF(E18="","",IFERROR(IF(N18="",P18/O18,P18/N18),"")) | T18: =IFERROR(IF(S18="","",S18/Q18*365/12),"") | U18: =IFERROR(IF(S18="","",S18/Q18*365),"")
H19: =IFERROR(__xludf.DUMMYFUNCTION("IF(F19="""","""",IFERROR(GOOGLEFINANCE(UPPER(F19),""price""),""""))"),"") | J19: =IF(OR(A19="",E19<>""),"",IFERROR(H19-I19,"")) | P19: =IF(A19="","",IF(A19="Sell",IF(M19="","", (L19-M19)*K19*100),IF(A19="Assigned",IF(L19="","",L19*K19*100),IF(A19="Buy",IF(M19="","",(M19-L19)*K19*100),"")))) | Q19: =IF(E19="","",IF(E19-C19<1,1,E19-C19)) | R19: =IFERROR(IF(P19="","",P19/Q19),"") | S19: =IF(E19="","",IFERROR(IF(N19="",P19/O19,P19/N19),"")) | T19: =IFERROR(IF(S19="","",S19/Q19*365/12),"") | U19: =IFERROR(IF(S19="","",S19/Q19*365),"")
H20: =IFERROR(__xludf.DUMMYFUNCTION("IF(F20="""","""",IFERROR(GOOGLEFINANCE(UPPER(F20),""price""),""""))"),"") | J20: =IF(OR(A20="",E20<>""),"",IFERROR(H20-I20,"")) | P20: =IF(A20="","",IF(A20="Sell",IF(M20="","", (L20-M20)*K20*100),IF(A20="Assigned",IF(L20="","",L20*K20*100),IF(A20="Buy",IF(M20="","",(M20-L20)*K20*100),"")))) | Q20: =IF(E20="","",IF(E20-C20<1,1,E20-C20)) | R20: =IFERROR(IF(P20="","",P20/Q20),"") | S20: =IF(E20="","",IFERROR(IF(N20="",P20/O20,P20/N20),"")) | T20: =IFERROR(IF(S20="","",S20/Q20*365/12),"") | U20: =IFERROR(IF(S20="","",S20/Q20*365),"")
H21: =IFERROR(__xludf.DUMMYFUNCTION("IF(F21="""","""",IFERROR(GOOGLEFINANCE(UPPER(F21),""price""),""""))"),"") | J21: =IF(OR(A21="",E21<>""),"",IFERROR(H21-I21,"")) | P21: =IF(A21="","",IF(A21="Sell",IF(M21="","", (L21-M21)*K21*100),IF(A21="Assigned",IF(L21="","",L21*K21*100),IF(A21="Buy",IF(M21="","",(M21-L21)*K21*100),"")))) | Q21: =IF(E21="","",IF(E21-C21<1,1,E21-C21)) | R21: =IFERROR(IF(P21="","",P21/Q21),"") | S21: =IF(E21="","",IFERROR(IF(N21="",P21/O21,P21/N21),"")) | T21: =IFERROR(IF(S21="","",S21/Q21*365/12),"") | U21: =IFERROR(IF(S21="","",S21/Q21*365),"")
H22: =IFERROR(__xludf.DUMMYFUNCTION("IF(F22="""","""",IFERROR(GOOGLEFINANCE(UPPER(F22),""price""),""""))"),"") | J22: =IF(OR(A22="",E22<>""),"",IFERROR(H22-I22,"")) | P22: =IF(A22="","",IF(A22="Sell",IF(M22="","", (L22-M22)*K22*100),IF(A22="Assigned",IF(L22="","",L22*K22*100),IF(A22="Buy",IF(M22="","",(M22-L22)*K22*100),"")))) | Q22: =IF(E22="","",IF(E22-C22<1,1,E22-C22)) | R22: =IFERROR(IF(P22="","",P22/Q22),"") | S22: =IF(E22="","",IFERROR(IF(N22="",P22/O22,P22/N22),"")) | T22: =IFERROR(IF(S22="","",S22/Q22*365/12),"") | U22: =IFERROR(IF(S22="","",S22/Q22*365),"")
H23: =IFERROR(__xludf.DUMMYFUNCTION("IF(F23="""","""",IFERROR(GOOGLEFINANCE(UPPER(F23),""price""),""""))"),"") | J23: =IF(OR(A23="",E23<>""),"",IFERROR(H23-I23,"")) | P23: =IF(A23="","",IF(A23="Sell",IF(M23="","", (L23-M23)*K23*100),IF(A23="Assigned",IF(L23="","",L23*K23*100),IF(A23="Buy",IF(M23="","",(M23-L23)*K23*100),"")))) | Q23: =IF(E23="","",IF(E23-C23<1,1,E23-C23)) | R23: =IFERROR(IF(P23="","",P23/Q23),"") | S23: =IF(E23="","",IFERROR(IF(N23="",P23/O23,P23/N23),"")) | T23: =IFERROR(IF(S23="","",S23/Q23*365/12),"") | U23: =IFERROR(IF(S23="","",S23/Q23*365),"")
H24: =IFERROR(__xludf.DUMMYFUNCTION("IF(F24="""","""",IFERROR(GOOGLEFINANCE(UPPER(F24),""price""),""""))"),"") | J24: =IF(OR(A24="",E24<>""),"",IFERROR(H24-I24,"")) | P24: =IF(A24="","",IF(A24="Sell",IF(M24="","", (L24-M24)*K24*100),IF(A24="Assigned",IF(L24="","",L24*K24*100),IF(A24="Buy",IF(M24="","",(M24-L24)*K24*100),"")))) | Q24: =IF(E24="","",IF(E24-C24<1,1,E24-C24)) | R24: =IFERROR(IF(P24="","",P24/Q24),"") | S24: =IF(E24="","",IFERROR(IF(N24="",P24/O24,P24/N24),"")) | T24: =IFERROR(IF(S24="","",S24/Q24*365/12),"") | U24: =IFERROR(IF(S24="","",S24/Q24*365),"")
H25: =IFERROR(__xludf.DUMMYFUNCTION("IF(F25="""","""",IFERROR(GOOGLEFINANCE(UPPER(F25),""price""),""""))"),"") | J25: =IF(OR(A25="",E25<>""),"",IFERROR(H25-I25,"")) | P25: =IF(A25="","",IF(A25="Sell",IF(M25="","", (L25-M25)*K25*100),IF(A25="Assigned",IF(L25="","",L25*K25*100),IF(A25="Buy",IF(M25="","",(M25-L25)*K25*100),"")))) | Q25: =IF(E25="","",IF(E25-C25<1,1,E25-C25)) | R25: =IFERROR(IF(P25="","",P25/Q25),"") | S25: =IF(E25="","",IFERROR(IF(N25="",P25/O25,P25/N25),"")) | T25: =IFERROR(IF(S25="","",S25/Q25*365/12),"") | U25: =IFERROR(IF(S25="","",S25/Q25*365),"")
H26: =IFERROR(__xludf.DUMMYFUNCTION("IF(F26="""","""",IFERROR(GOOGLEFINANCE(UPPER(F26),""price""),""""))"),"") | J26: =IF(OR(A26="",E26<>""),"",IFERROR(H26-I26,"")) | P26: =IF(A26="","",IF(A26="Sell",IF(M26="","", (L26-M26)*K26*100),IF(A26="Assigned",IF(L26="","",L26*K26*100),IF(A26="Buy",IF(M26="","",(M26-L26)*K26*100),"")))) | Q26: =IF(E26="","",IF(E26-C26<1,1,E26-C26)) | R26: =IFERROR(IF(P26="","",P26/Q26),"") | S26: =IF(E26="","",IFERROR(IF(N26="",P26/O26,P26/N26),"")) | T26: =IFERROR(IF(S26="","",S26/Q26*365/12),"") | U26: =IFERROR(IF(S26="","",S26/Q26*365),"")
H27: =IFERROR(__xludf.DUMMYFUNCTION("IF(F27="""","""",IFERROR(GOOGLEFINANCE(UPPER(F27),""price""),""""))"),"") | J27: =IF(OR(A27="",E27<>""),"",IFERROR(H27-I27,"")) | P27: =IF(A27="","",IF(A27="Sell",IF(M27="","", (L27-M27)*K27*100),IF(A27="Assigned",IF(L27="","",L27*K27*100),IF(A27="Buy",IF(M27="","",(M27-L27)*K27*100),"")))) | Q27: =IF(E27="","",IF(E27-C27<1,1,E27-C27)) | R27: =IFERROR(IF(P27="","",P27/Q27),"") | S27: =IF(E27="","",IFERROR(IF(N27="",P27/O27,P27/N27),"")) | T27: =IFERROR(IF(S27="","",S27/Q27*365/12),"") | U27: =IFERROR(IF(S27="","",S27/Q27*365),"")
H28: =IFERROR(__xludf.DUMMYFUNCTION("IF(F28="""","""",IFERROR(GOOGLEFINANCE(UPPER(F28),""price""),""""))"),"") | J28: =IF(OR(A28="",E28<>""),"",IFERROR(H28-I28,"")) | P28: =IF(A28="","",IF(A28="Sell",IF(M28="","", (L28-M28)*K28*100),IF(A28="Assigned",IF(L28="","",L28*K28*100),IF(A28="Buy",IF(M28="","",(M28-L28)*K28*100),"")))) | Q28: =IF(E28="","",IF(E28-C28<1,1,E28-C28)) | R28: =IFERROR(IF(P28="","",P28/Q28),"") | S28: =IF(E28="","",IFERROR(IF(N28="",P28/O28,P28/N28),"")) | T28: =IFERROR(IF(S28="","",S28/Q28*365/12),"") | U28: =IFERROR(IF(S28="","",S28/Q28*365),"")
H29: =IFERROR(__xludf.DUMMYFUNCTION("IF(F29="""","""",IFERROR(GOOGLEFINANCE(UPPER(F29),""price""),""""))"),"") | J29: =IF(OR(A29="",E29<>""),"",IFERROR(H29-I29,"")) | P29: =IF(A29="","",IF(A29="Sell",IF(M29="","", (L29-M29)*K29*100),IF(A29="Assigned",IF(L29="","",L29*K29*100),IF(A29="Buy",IF(M29="","",(M29-L29)*K29*100),"")))) | Q29: =IF(E29="","",IF(E29-C29<1,1,E29-C29)) | R29: =IFERROR(IF(P29="","",P29/Q29),"") | S29: =IF(E29="","",IFERROR(IF(N29="",P29/O29,P29/N29),"")) | T29: =IFERROR(IF(S29="","",S29/Q29*365/12),"") | U29: =IFERROR(IF(S29="","",S29/Q29*365),"")
H30: =IFERROR(__xludf.DUMMYFUNCTION("IF(F30="""","""",IFERROR(GOOGLEFINANCE(UPPER(F30),""price""),""""))"),"") | J30: =IF(OR(A30="",E30<>""),"",IFERROR(H30-I30,"")) | P30: =IF(A30="","",IF(A30="Sell",IF(M30="","", (L30-M30)*K30*100),IF(A30="Assigned",IF(L30="","",L30*K30*100),IF(A30="Buy",IF(M30="","",(M30-L30)*K30*100),"")))) | Q30: =IF(E30="","",IF(E30-C30<1,1,E30-C30)) | R30: =IFERROR(IF(P30="","",P30/Q30),"") | S30: =IF(E30="","",IFERROR(IF(N30="",P30/O30,P30/N30),"")) | T30: =IFERROR(IF(S30="","",S30/Q30*365/12),"") | U30: =IFERROR(IF(S30="","",S30/Q30*365),"")
H31: =IFERROR(__xludf.DUMMYFUNCTION("IF(F31="""","""",IFERROR(GOOGLEFINANCE(UPPER(F31),""price""),""""))"),"") | J31: =IF(OR(A31="",E31<>""),"",IFERROR(H31-I31,"")) | P31: =IF(A31="","",IF(A31="Sell",IF(M31="","", (L31-M31)*K31*100),IF(A31="Assigned",IF(L31="","",L31*K31*100),IF(A31="Buy",IF(M31="","",(M31-L31)*K31*100),"")))) | Q31: =IF(E31="","",IF(E31-C31<1,1,E31-C31)) | R31: =IFERROR(IF(P31="","",P31/Q31),"") | S31: =IF(E31="","",IFERROR(IF(N31="",P31/O31,P31/N31),"")) | T31: =IFERROR(IF(S31="","",S31/Q31*365/12),"") | U31: =IFERROR(IF(S31="","",S31/Q31*365),"")
H32: =IFERROR(__xludf.DUMMYFUNCTION("IF(F32="""","""",IFERROR(GOOGLEFINANCE(UPPER(F32),""price""),""""))"),"") | J32: =IF(OR(A32="",E32<>""),"",IFERROR(H32-I32,"")) | P32: =IF(A32="","",IF(A32="Sell",IF(M32="","", (L32-M32)*K32*100),IF(A32="Assigned",IF(L32="","",L32*K32*100),IF(A32="Buy",IF(M32="","",(M32-L32)*K32*100),"")))) | Q32: =IF(E32="","",IF(E32-C32<1,1,E32-C32)) | R32: =IFERROR(IF(P32="","",P32/Q32),"") | S32: =IF(E32="","",IFERROR(IF(N32="",P32/O32,P32/N32),"")) | T32: =IFERROR(IF(S32="","",S32/Q32*365/12),"") | U32: =IFERROR(IF(S32="","",S32/Q32*365),"")
H33: =IFERROR(__xludf.DUMMYFUNCTION("IF(F33="""","""",IFERROR(GOOGLEFINANCE(UPPER(F33),""price""),""""))"),"") | J33: =IF(OR(A33="",E33<>""),"",IFERROR(H33-I33,"")) | P33: =IF(A33="","",IF(A33="Sell",IF(M33="","", (L33-M33)*K33*100),IF(A33="Assigned",IF(L33="","",L33*K33*100),IF(A33="Buy",IF(M33="","",(M33-L33)*K33*100),"")))) | Q33: =IF(E33="","",IF(E33-C33<1,1,E33-C33)) | R33: =IFERROR(IF(P33="","",P33/Q33),"") | S33: =IF(E33="","",IFERROR(IF(N33="",P33/O33,P33/N33),"")) | T33: =IFERROR(IF(S33="","",S33/Q33*365/12),"") | U33: =IFERROR(IF(S33="","",S33/Q33*365),"")
H34: =IFERROR(__xludf.DUMMYFUNCTION("IF(F34="""","""",IFERROR(GOOGLEFINANCE(UPPER(F34),""price""),""""))"),"") | J34: =IF(OR(A34="",E34<>""),"",IFERROR(H34-I34,"")) | P34: =IF(A34="","",IF(A34="Sell",IF(M34="","", (L34-M34)*K34*100),IF(A34="Assigned",IF(L34="","",L34*K34*100),IF(A34="Buy",IF(M34="","",(M34-L34)*K34*100),"")))) | Q34: =IF(E34="","",IF(E34-C34<1,1,E34-C34)) | R34: =IFERROR(IF(P34="","",P34/Q34),"") | S34: =IF(E34="","",IFERROR(IF(N34="",P34/O34,P34/N34),"")) | T34: =IFERROR(IF(S34="","",S34/Q34*365/12),"") | U34: =IFERROR(IF(S34="","",S34/Q34*365),"")
H35: =IFERROR(__xludf.DUMMYFUNCTION("IF(F35="""","""",IFERROR(GOOGLEFINANCE(UPPER(F35),""price""),""""))"),"") | J35: =IF(OR(A35="",E35<>""),"",IFERROR(H35-I35,"")) | P35: =IF(A35="","",IF(A35="Sell",IF(M35="","", (L35-M35)*K35*100),IF(A35="Assigned",IF(L35="","",L35*K35*100),IF(A35="Buy",IF(M35="","",(M35-L35)*K35*100),"")))) | Q35: =IF(E35="","",IF(E35-C35<1,1,E35-C35)) | R35: =IFERROR(IF(P35="","",P35/Q35),"") | S35: =IF(E35="","",IFERROR(IF(N35="",P35/O35,P35/N35),"")) | T35: =IFERROR(IF(S35="","",S35/Q35*365/12),"") | U35: =IFERROR(IF(S35="","",S35/Q35*365),"")
H36: =IFERROR(__xludf.DUMMYFUNCTION("IF(F36="""","""",IFERROR(GOOGLEFINANCE(UPPER(F36),""price""),""""))"),"") | J36: =IF(OR(A36="",E36<>""),"",IFERROR(H36-I36,"")) | P36: =IF(A36="","",IF(A36="Sell",IF(M36="","", (L36-M36)*K36*100),IF(A36="Assigned",IF(L36="","",L36*K36*100),IF(A36="Buy",IF(M36="","",(M36-L36)*K36*100),"")))) | Q36: =IF(E36="","",IF(E36-C36<1,1,E36-C36)) | R36: =IFERROR(IF(P36="","",P36/Q36),"") | S36: =IF(E36="","",IFERROR(IF(N36="",P36/O36,P36/N36),"")) | T36: =IFERROR(IF(S36="","",S36/Q36*365/12),"") | U36: =IFERROR(IF(S36="","",S36/Q36*365),"")
H37: =IFERROR(__xludf.DUMMYFUNCTION("IF(F37="""","""",IFERROR(GOOGLEFINANCE(UPPER(F37),""price""),""""))"),"") | J37: =IF(OR(A37="",E37<>""),"",IFERROR(H37-I37,"")) | P37: =IF(A37="","",IF(A37="Sell",IF(M37="","", (L37-M37)*K37*100),IF(A37="Assigned",IF(L37="","",L37*K37*100),IF(A37="Buy",IF(M37="","",(M37-L37)*K37*100),"")))) | Q37: =IF(E37="","",IF(E37-C37<1,1,E37-C37)) | R37: =IFERROR(IF(P37="","",P37/Q37),"") | S37: =IF(E37="","",IFERROR(IF(N37="",P37/O37,P37/N37),"")) | T37: =IFERROR(IF(S37="","",S37/Q37*365/12),"") | U37: =IFERROR(IF(S37="","",S37/Q37*365),"")
H38: =IFERROR(__xludf.DUMMYFUNCTION("IF(F38="""","""",IFERROR(GOOGLEFINANCE(UPPER(F38),""price""),""""))"),"") | J38: =IF(OR(A38="",E38<>""),"",IFERROR(H38-I38,"")) | P38: =IF(A38="","",IF(A38="Sell",IF(M38="","", (L38-M38)*K38*100),IF(A38="Assigned",IF(L38="","",L38*K38*100),IF(A38="Buy",IF(M38="","",(M38-L38)*K38*100),"")))) | Q38: =IF(E38="","",IF(E38-C38<1,1,E38-C38)) | R38: =IFERROR(IF(P38="","",P38/Q38),"") | S38: =IF(E38="","",IFERROR(IF(N38="",P38/O38,P38/N38),"")) | T38: =IFERROR(IF(S38="","",S38/Q38*365/12),"") | U38: =IFERROR(IF(S38="","",S38/Q38*365),"")
H39: =IFERROR(__xludf.DUMMYFUNCTION("IF(F39="""","""",IFERROR(GOOGLEFINANCE(UPPER(F39),""price""),""""))"),"") | J39: =IF(OR(A39="",E39<>""),"",IFERROR(H39-I39,"")) | P39: =IF(A39="","",IF(A39="Sell",IF(M39="","", (L39-M39)*K39*100),IF(A39="Assigned",IF(L39="","",L39*K39*100),IF(A39="Buy",IF(M39="","",(M39-L39)*K39*100),"")))) | Q39: =IF(E39="","",IF(E39-C39<1,1,E39-C39)) | R39: =IFERROR(IF(P39="","",P39/Q39),"") | S39: =IF(E39="","",IFERROR(IF(N39="",P39/O39,P39/N39),"")) | T39: =IFERROR(IF(S39="","",S39/Q39*365/12),"") | U39: =IFERROR(IF(S39="","",S39/Q39*365),"")
H40: =IFERROR(__xludf.DUMMYFUNCTION("IF(F40="""","""",IFERROR(GOOGLEFINANCE(UPPER(F40),""price""),""""))"),"") | J40: =IF(OR(A40="",E40<>""),"",IFERROR(H40-I40,"")) | P40: =IF(A40="","",IF(A40="Sell",IF(M40="","", (L40-M40)*K40*100),IF(A40="Assigned",IF(L40="","",L40*K40*100),IF(A40="Buy",IF(M40="","",(M40-L40)*K40*100),"")))) | Q40: =IF(E40="","",IF(E40-C40<1,1,E40-C40)) | R40: =IFERROR(IF(P40="","",P40/Q40),"") | S40: =IF(E40="","",IFERROR(IF(N40="",P40/O40,P40/N40),"")) | T40: =IFERROR(IF(S40="","",S40/Q40*365/12),"") | U40: =IFERROR(IF(S40="","",S40/Q40*365),"")
...

Sheet Call & Puts
A1: Practical Income Investing - calls & puts
A2: TOTAL PROFIT | E2: =SUM(P5:P304) -> 0 | J2: COLLATERAL USED | N2: =IFERROR(SUMIF(E5:E304,"<>",O5:O304),0) -> 0 | P2: TOTAL ROC | S2: =IFERROR(E2/N2,0) -> 0 | V2: Locked Cells | W2: Manually Enter
A3: WINS | C3: =COUNTIF(P5:P304,">0") -> 0 | D3: LOSSES | F3: =COUNTIF(P5:P304,"<0") -> 0 | H3: WIN RATE | K3: =IFERROR(C3/(C3+F3),0) -> 0 | M3: AVG WIN | O3: =IFERROR(AVERAGEIF(P5:P304,">0"),0) -> 0 | Q3: AVG LOSS | S3: =IFERROR(AVERAGEIF(P5:P304,"<0"),0) -> 0 | V3: Cell Use Guide
A4: TYPE | B4: STRATEGY | C4: OPEN DATE | D4: EXP DATE | E4: CLOSE DATE | F4: TICKER | G4: BROKERAGE | H4: TODAY'S PRICE | I4: STRIKE $ | J4: BREACH ALERT | K4: QTY | L4: PREMIUM $ | M4: CLOSE $ | N4: CC COLLATERAL | O4: COLLATERAL $ | P4: P / L | Q4: #DAYS | R4: PROFIT PER DAY | S4: RETURN ON CAPITAL | T4: MONTHLY RETURN % | U4: ANNUAL RETURN % | V4: NOTES
H5: =IFERROR(__xludf.DUMMYFUNCTION("IF(F5="""","""",IFERROR(GOOGLEFINANCE(UPPER(F5),""price""),""""))"),"") | J5: =IF(OR(A5="",E5<>""),"",IFERROR(H5-I5,"")) | O5: =IF(A5="Buy",IF(L5="","",L5*K5*100),IF(A5="Assigned",IF(L5="","",L5*K5*100),IF(A5="Sell",IF(OR(I5="",K5=""),"",I5*K5*100),""))) | P5: =IF(M5="","",IF(A5="Sell",(L5-M5)*K5*100,IF(OR(A5="Buy",A5="Assigned"),(M5-L5)*K5*100,""))) | Q5: =IF(E5="","",IF(E5-C5<1,1,E5-C5)) | R5: =IFERROR(IF(P5="","",P5/Q5),"") | S5: =IF(E5="","",IFERROR(IF(N5="",P5/O5,P5/N5),"")) | T5: =IFERROR(IF(S5="","",S5/Q5*365/12),"") | U5: =IFERROR(IF(S5="","",S5/Q5*365),"")
H6: =IFERROR(__xludf.DUMMYFUNCTION("IF(F6="""","""",IFERROR(GOOGLEFINANCE(UPPER(F6),""price""),""""))"),"") | J6: =IF(OR(A6="",E6<>""),"",IFERROR(H6-I6,"")) | O6: =IF(A6="Buy",IF(L6="","",L6*K6*100),IF(A6="Assigned",IF(L6="","",L6*K6*100),IF(A6="Sell",IF(OR(I6="",K6=""),"",I6*K6*100),""))) | P6: =IF(M6="","",IF(A6="Sell",(L6-M6)*K6*100,IF(OR(A6="Buy",A6="Assigned"),(M6-L6)*K6*100,""))) | Q6: =IF(E6="","",IF(E6-C6<1,1,E6-C6)) | R6: =IFERROR(IF(P6="","",P6/Q6),"") | S6: =IF(E6="","",IFERROR(IF(N6="",P6/O6,P6/N6),"")) | T6: =IFERROR(IF(S6="","",S6/Q6*365/12),"") | U6: =IFERROR(IF(S6="","",S6/Q6*365),"")
H7: =IFERROR(__xludf.DUMMYFUNCTION("IF(F7="""","""",IFERROR(GOOGLEFINANCE(UPPER(F7),""price""),""""))"),"") | J7: =IF(OR(A7="",E7<>""),"",IFERROR(H7-I7,"")) | O7: =IF(A7="Buy",IF(L7="","",L7*K7*100),IF(A7="Assigned",IF(L7="","",L7*K7*100),IF(A7="Sell",IF(OR(I7="",K7=""),"",I7*K7*100),""))) | P7: =IF(M7="","",IF(A7="Sell",(L7-M7)*K7*100,IF(OR(A7="Buy",A7="Assigned"),(M7-L7)*K7*100,""))) | Q7: =IF(E7="","",IF(E7-C7<1,1,E7-C7)) | R7: =IFERROR(IF(P7="","",P7/Q7),"") | S7: =IF(E7="","",IFERROR(IF(N7="",P7/O7,P7/N7),"")) | T7: =IFERROR(IF(S7="","",S7/Q7*365/12),"") | U7: =IFERROR(IF(S7="","",S7/Q7*365),"")
H8: =IFERROR(__xludf.DUMMYFUNCTION("IF(F8="""","""",IFERROR(GOOGLEFINANCE(UPPER(F8),""price""),""""))"),"") | J8: =IF(OR(A8="",E8<>""),"",IFERROR(H8-I8,"")) | O8: =IF(A8="Buy",IF(L8="","",L8*K8*100),IF(A8="Assigned",IF(L8="","",L8*K8*100),IF(A8="Sell",IF(OR(I8="",K8=""),"",I8*K8*100),""))) | P8: =IF(M8="","",IF(A8="Sell",(L8-M8)*K8*100,IF(OR(A8="Buy",A8="Assigned"),(M8-L8)*K8*100,""))) | Q8: =IF(E8="","",IF(E8-C8<1,1,E8-C8)) | R8: =IFERROR(IF(P8="","",P8/Q8),"") | S8: =IF(E8="","",IFERROR(IF(N8="",P8/O8,P8/N8),"")) | T8: =IFERROR(IF(S8="","",S8/Q8*365/12),"") | U8: =IFERROR(IF(S8="","",S8/Q8*365),"")
H9: =IFERROR(__xludf.DUMMYFUNCTION("IF(F9="""","""",IFERROR(GOOGLEFINANCE(UPPER(F9),""price""),""""))"),"") | J9: =IF(OR(A9="",E9<>""),"",IFERROR(H9-I9,"")) | O9: =IF(A9="Buy",IF(L9="","",L9*K9*100),IF(A9="Assigned",IF(L9="","",L9*K9*100),IF(A9="Sell",IF(OR(I9="",K9=""),"",I9*K9*100),""))) | P9: =IF(M9="","",IF(A9="Sell",(L9-M9)*K9*100,IF(OR(A9="Buy",A9="Assigned"),(M9-L9)*K9*100,""))) | Q9: =IF(E9="","",IF(E9-C9<1,1,E9-C9)) | R9: =IFERROR(IF(P9="","",P9/Q9),"") | S9: =IF(E9="","",IFERROR(IF(N9="",P9/O9,P9/N9),"")) | T9: =IFERROR(IF(S9="","",S9/Q9*365/12),"") | U9: =IFERROR(IF(S9="","",S9/Q9*365),"")
H10: =IFERROR(__xludf.DUMMYFUNCTION("IF(F10="""","""",IFERROR(GOOGLEFINANCE(UPPER(F10),""price""),""""))"),"") | J10: =IF(OR(A10="",E10<>""),"",IFERROR(H10-I10,"")) | O10: =IF(A10="Buy",IF(L10="","",L10*K10*100),IF(A10="Assigned",IF(L10="","",L10*K10*100),IF(A10="Sell",IF(OR(I10="",K10=""),"",I10*K10*100),""))) | P10: =IF(M10="","",IF(A10="Sell",(L10-M10)*K10*100,IF(OR(A10="Buy",A10="Assigned"),(M10-L10)*K10*100,""))) | Q10: =IF(E10="","",IF(E10-C10<1,1,E10-C10)) | R10: =IFERROR(IF(P10="","",P10/Q10),"") | S10: =IF(E10="","",IFERROR(IF(N10="",P10/O10,P10/N10),"")) | T10: =IFERROR(IF(S10="","",S10/Q10*365/12),"") | U10: =IFERROR(IF(S10="","",S10/Q10*365),"")
H11: =IFERROR(__xludf.DUMMYFUNCTION("IF(F11="""","""",IFERROR(GOOGLEFINANCE(UPPER(F11),""price""),""""))"),"") | J11: =IF(OR(A11="",E11<>""),"",IFERROR(H11-I11,"")) | O11: =IF(A11="Buy",IF(L11="","",L11*K11*100),IF(A11="Assigned",IF(L11="","",L11*K11*100),IF(A11="Sell",IF(OR(I11="",K11=""),"",I11*K11*100),""))) | P11: =IF(M11="","",IF(A11="Sell",(L11-M11)*K11*100,IF(OR(A11="Buy",A11="Assigned"),(M11-L11)*K11*100,""))) | Q11: =IF(E11="","",IF(E11-C11<1,1,E11-C11)) | R11: =IFERROR(IF(P11="","",P11/Q11),"") | S11: =IF(E11="","",IFERROR(IF(N11="",P11/O11,P11/N11),"")) | T11: =IFERROR(IF(S11="","",S11/Q11*365/12),"") | U11: =IFERROR(IF(S11="","",S11/Q11*365),"")
H12: =IFERROR(__xludf.DUMMYFUNCTION("IF(F12="""","""",IFERROR(GOOGLEFINANCE(UPPER(F12),""price""),""""))"),"") | J12: =IF(OR(A12="",E12<>""),"",IFERROR(H12-I12,"")) | O12: =IF(A12="Buy",IF(L12="","",L12*K12*100),IF(A12="Assigned",IF(L12="","",L12*K12*100),IF(A12="Sell",IF(OR(I12="",K12=""),"",I12*K12*100),""))) | P12: =IF(M12="","",IF(A12="Sell",(L12-M12)*K12*100,IF(OR(A12="Buy",A12="Assigned"),(M12-L12)*K12*100,""))) | Q12: =IF(E12="","",IF(E12-C12<1,1,E12-C12)) | R12: =IFERROR(IF(P12="","",P12/Q12),"") | S12: =IF(E12="","",IFERROR(IF(N12="",P12/O12,P12/N12),"")) | T12: =IFERROR(IF(S12="","",S12/Q12*365/12),"") | U12: =IFERROR(IF(S12="","",S12/Q12*365),"")
H13: =IFERROR(__xludf.DUMMYFUNCTION("IF(F13="""","""",IFERROR(GOOGLEFINANCE(UPPER(F13),""price""),""""))"),"") | J13: =IF(OR(A13="",E13<>""),"",IFERROR(H13-I13,"")) | O13: =IF(A13="Buy",IF(L13="","",L13*K13*100),IF(A13="Assigned",IF(L13="","",L13*K13*100),IF(A13="Sell",IF(OR(I13="",K13=""),"",I13*K13*100),""))) | P13: =IF(M13="","",IF(A13="Sell",(L13-M13)*K13*100,IF(OR(A13="Buy",A13="Assigned"),(M13-L13)*K13*100,""))) | Q13: =IF(E13="","",IF(E13-C13<1,1,E13-C13)) | R13: =IFERROR(IF(P13="","",P13/Q13),"") | S13: =IF(E13="","",IFERROR(IF(N13="",P13/O13,P13/N13),"")) | T13: =IFERROR(IF(S13="","",S13/Q13*365/12),"") | U13: =IFERROR(IF(S13="","",S13/Q13*365),"")
H14: =IFERROR(__xludf.DUMMYFUNCTION("IF(F14="""","""",IFERROR(GOOGLEFINANCE(UPPER(F14),""price""),""""))"),"") | J14: =IF(OR(A14="",E14<>""),"",IFERROR(H14-I14,"")) | O14: =IF(A14="Buy",IF(L14="","",L14*K14*100),IF(A14="Assigned",IF(L14="","",L14*K14*100),IF(A14="Sell",IF(OR(I14="",K14=""),"",I14*K14*100),""))) | P14: =IF(M14="","",IF(A14="Sell",(L14-M14)*K14*100,IF(OR(A14="Buy",A14="Assigned"),(M14-L14)*K14*100,""))) | Q14: =IF(E14="","",IF(E14-C14<1,1,E14-C14)) | R14: =IFERROR(IF(P14="","",P14/Q14),"") | S14: =IF(E14="","",IFERROR(IF(N14="",P14/O14,P14/N14),"")) | T14: =IFERROR(IF(S14="","",S14/Q14*365/12),"") | U14: =IFERROR(IF(S14="","",S14/Q14*365),"")
H15: =IFERROR(__xludf.DUMMYFUNCTION("IF(F15="""","""",IFERROR(GOOGLEFINANCE(UPPER(F15),""price""),""""))"),"") | J15: =IF(OR(A15="",E15<>""),"",IFERROR(H15-I15,"")) | O15: =IF(A15="Buy",IF(L15="","",L15*K15*100),IF(A15="Assigned",IF(L15="","",L15*K15*100),IF(A15="Sell",IF(OR(I15="",K15=""),"",I15*K15*100),""))) | P15: =IF(M15="","",IF(A15="Sell",(L15-M15)*K15*100,IF(OR(A15="Buy",A15="Assigned"),(M15-L15)*K15*100,""))) | Q15: =IF(E15="","",IF(E15-C15<1,1,E15-C15)) | R15: =IFERROR(IF(P15="","",P15/Q15),"") | S15: =IF(E15="","",IFERROR(IF(N15="",P15/O15,P15/N15),"")) | T15: =IFERROR(IF(S15="","",S15/Q15*365/12),"") | U15: =IFERROR(IF(S15="","",S15/Q15*365),"")
H16: =IFERROR(__xludf.DUMMYFUNCTION("IF(F16="""","""",IFERROR(GOOGLEFINANCE(UPPER(F16),""price""),""""))"),"") | J16: =IF(OR(A16="",E16<>""),"",IFERROR(H16-I16,"")) | O16: =IF(A16="Buy",IF(L16="","",L16*K16*100),IF(A16="Assigned",IF(L16="","",L16*K16*100),IF(A16="Sell",IF(OR(I16="",K16=""),"",I16*K16*100),""))) | P16: =IF(M16="","",IF(A16="Sell",(L16-M16)*K16*100,IF(OR(A16="Buy",A16="Assigned"),(M16-L16)*K16*100,""))) | Q16: =IF(E16="","",IF(E16-C16<1,1,E16-C16)) | R16: =IFERROR(IF(P16="","",P16/Q16),"") | S16: =IF(E16="","",IFERROR(IF(N16="",P16/O16,P16/N16),"")) | T16: =IFERROR(IF(S16="","",S16/Q16*365/12),"") | U16: =IFERROR(IF(S16="","",S16/Q16*365),"")
H17: =IFERROR(__xludf.DUMMYFUNCTION("IF(F17="""","""",IFERROR(GOOGLEFINANCE(UPPER(F17),""price""),""""))"),"") | J17: =IF(OR(A17="",E17<>""),"",IFERROR(H17-I17,"")) | O17: =IF(A17="Buy",IF(L17="","",L17*K17*100),IF(A17="Assigned",IF(L17="","",L17*K17*100),IF(A17="Sell",IF(OR(I17="",K17=""),"",I17*K17*100),""))) | P17: =IF(M17="","",IF(A17="Sell",(L17-M17)*K17*100,IF(OR(A17="Buy",A17="Assigned"),(M17-L17)*K17*100,""))) | Q17: =IF(E17="","",IF(E17-C17<1,1,E17-C17)) | R17: =IFERROR(IF(P17="","",P17/Q17),"") | S17: =IF(E17="","",IFERROR(IF(N17="",P17/O17,P17/N17),"")) | T17: =IFERROR(IF(S17="","",S17/Q17*365/12),"") | U17: =IFERROR(IF(S17="","",S17/Q17*365),"")
H18: =IFERROR(__xludf.DUMMYFUNCTION("IF(F18="""","""",IFERROR(GOOGLEFINANCE(UPPER(F18),""price""),""""))"),"") | J18: =IF(OR(A18="",E18<>""),"",IFERROR(H18-I18,"")) | O18: =IF(A18="Buy",IF(L18="","",L18*K18*100),IF(A18="Assigned",IF(L18="","",L18*K18*100),IF(A18="Sell",IF(OR(I18="",K18=""),"",I18*K18*100),""))) | P18: =IF(M18="","",IF(A18="Sell",(L18-M18)*K18*100,IF(OR(A18="Buy",A18="Assigned"),(M18-L18)*K18*100,""))) | Q18: =IF(E18="","",IF(E18-C18<1,1,E18-C18)) | R18: =IFERROR(IF(P18="","",P18/Q18),"") | S18: =IF(E18="","",IFERROR(IF(N18="",P18/O18,P18/N18),"")) | T18: =IFERROR(IF(S18="","",S18/Q18*365/12),"") | U18: =IFERROR(IF(S18="","",S18/Q18*365),"")
H19: =IFERROR(__xludf.DUMMYFUNCTION("IF(F19="""","""",IFERROR(GOOGLEFINANCE(UPPER(F19),""price""),""""))"),"") | J19: =IF(OR(A19="",E19<>""),"",IFERROR(H19-I19,"")) | O19: =IF(A19="Buy",IF(L19="","",L19*K19*100),IF(A19="Assigned",IF(L19="","",L19*K19*100),IF(A19="Sell",IF(OR(I19="",K19=""),"",I19*K19*100),""))) | P19: =IF(M19="","",IF(A19="Sell",(L19-M19)*K19*100,IF(OR(A19="Buy",A19="Assigned"),(M19-L19)*K19*100,""))) | Q19: =IF(E19="","",IF(E19-C19<1,1,E19-C19)) | R19: =IFERROR(IF(P19="","",P19/Q19),"") | S19: =IF(E19="","",IFERROR(IF(N19="",P19/O19,P19/N19),"")) | T19: =IFERROR(IF(S19="","",S19/Q19*365/12),"") | U19: =IFERROR(IF(S19="","",S19/Q19*365),"")
H20: =IFERROR(__xludf.DUMMYFUNCTION("IF(F20="""","""",IFERROR(GOOGLEFINANCE(UPPER(F20),""price""),""""))"),"") | J20: =IF(OR(A20="",E20<>""),"",IFERROR(H20-I20,"")) | O20: =IF(A20="Buy",IF(L20="","",L20*K20*100),IF(A20="Assigned",IF(L20="","",L20*K20*100),IF(A20="Sell",IF(OR(I20="",K20=""),"",I20*K20*100),""))) | P20: =IF(M20="","",IF(A20="Sell",(L20-M20)*K20*100,IF(OR(A20="Buy",A20="Assigned"),(M20-L20)*K20*100,""))) | Q20: =IF(E20="","",IF(E20-C20<1,1,E20-C20)) | R20: =IFERROR(IF(P20="","",P20/Q20),"") | S20: =IF(E20="","",IFERROR(IF(N20="",P20/O20,P20/N20),"")) | T20: =IFERROR(IF(S20="","",S20/Q20*365/12),"") | U20: =IFERROR(IF(S20="","",S20/Q20*365),"")
H21: =IFERROR(__xludf.DUMMYFUNCTION("IF(F21="""","""",IFERROR(GOOGLEFINANCE(UPPER(F21),""price""),""""))"),"") | J21: =IF(OR(A21="",E21<>""),"",IFERROR(H21-I21,"")) | O21: =IF(A21="Buy",IF(L21="","",L21*K21*100),IF(A21="Assigned",IF(L21="","",L21*K21*100),IF(A21="Sell",IF(OR(I21="",K21=""),"",I21*K21*100),""))) | P21: =IF(M21="","",IF(A21="Sell",(L21-M21)*K21*100,IF(OR(A21="Buy",A21="Assigned"),(M21-L21)*K21*100,""))) | Q21: =IF(E21="","",IF(E21-C21<1,1,E21-C21)) | R21: =IFERROR(IF(P21="","",P21/Q21),"") | S21: =IF(E21="","",IFERROR(IF(N21="",P21/O21,P21/N21),"")) | T21: =IFERROR(IF(S21="","",S21/Q21*365/12),"") | U21: =IFERROR(IF(S21="","",S21/Q21*365),"")
H22: =IFERROR(__xludf.DUMMYFUNCTION("IF(F22="""","""",IFERROR(GOOGLEFINANCE(UPPER(F22),""price""),""""))"),"") | J22: =IF(OR(A22="",E22<>""),"",IFERROR(H22-I22,"")) | O22: =IF(A22="Buy",IF(L22="","",L22*K22*100),IF(A22="Assigned",IF(L22="","",L22*K22*100),IF(A22="Sell",IF(OR(I22="",K22=""),"",I22*K22*100),""))) | P22: =IF(M22="","",IF(A22="Sell",(L22-M22)*K22*100,IF(OR(A22="Buy",A22="Assigned"),(M22-L22)*K22*100,""))) | Q22: =IF(E22="","",IF(E22-C22<1,1,E22-C22)) | R22: =IFERROR(IF(P22="","",P22/Q22),"") | S22: =IF(E22="","",IFERROR(IF(N22="",P22/O22,P22/N22),"")) | T22: =IFERROR(IF(S22="","",S22/Q22*365/12),"") | U22: =IFERROR(IF(S22="","",S22/Q22*365),"")
H23: =IFERROR(__xludf.DUMMYFUNCTION("IF(F23="""","""",IFERROR(GOOGLEFINANCE(UPPER(F23),""price""),""""))"),"") | J23: =IF(OR(A23="",E23<>""),"",IFERROR(H23-I23,"")) | O23: =IF(A23="Buy",IF(L23="","",L23*K23*100),IF(A23="Assigned",IF(L23="","",L23*K23*100),IF(A23="Sell",IF(OR(I23="",K23=""),"",I23*K23*100),""))) | P23: =IF(M23="","",IF(A23="Sell",(L23-M23)*K23*100,IF(OR(A23="Buy",A23="Assigned"),(M23-L23)*K23*100,""))) | Q23: =IF(E23="","",IF(E23-C23<1,1,E23-C23)) | R23: =IFERROR(IF(P23="","",P23/Q23),"") | S23: =IF(E23="","",IFERROR(IF(N23="",P23/O23,P23/N23),"")) | T23: =IFERROR(IF(S23="","",S23/Q23*365/12),"") | U23: =IFERROR(IF(S23="","",S23/Q23*365),"")
H24: =IFERROR(__xludf.DUMMYFUNCTION("IF(F24="""","""",IFERROR(GOOGLEFINANCE(UPPER(F24),""price""),""""))"),"") | J24: =IF(OR(A24="",E24<>""),"",IFERROR(H24-I24,"")) | O24: =IF(A24="Buy",IF(L24="","",L24*K24*100),IF(A24="Assigned",IF(L24="","",L24*K24*100),IF(A24="Sell",IF(OR(I24="",K24=""),"",I24*K24*100),""))) | P24: =IF(M24="","",IF(A24="Sell",(L24-M24)*K24*100,IF(OR(A24="Buy",A24="Assigned"),(M24-L24)*K24*100,""))) | Q24: =IF(E24="","",IF(E24-C24<1,1,E24-C24)) | R24: =IFERROR(IF(P24="","",P24/Q24),"") | S24: =IF(E24="","",IFERROR(IF(N24="",P24/O24,P24/N24),"")) | T24: =IFERROR(IF(S24="","",S24/Q24*365/12),"") | U24: =IFERROR(IF(S24="","",S24/Q24*365),"")
H25: =IFERROR(__xludf.DUMMYFUNCTION("IF(F25="""","""",IFERROR(GOOGLEFINANCE(UPPER(F25),""price""),""""))"),"") | J25: =IF(OR(A25="",E25<>""),"",IFERROR(H25-I25,"")) | O25: =IF(A25="Buy",IF(L25="","",L25*K25*100),IF(A25="Assigned",IF(L25="","",L25*K25*100),IF(A25="Sell",IF(OR(I25="",K25=""),"",I25*K25*100),""))) | P25: =IF(M25="","",IF(A25="Sell",(L25-M25)*K25*100,IF(OR(A25="Buy",A25="Assigned"),(M25-L25)*K25*100,""))) | Q25: =IF(E25="","",IF(E25-C25<1,1,E25-C25)) | R25: =IFERROR(IF(P25="","",P25/Q25),"") | S25: =IF(E25="","",IFERROR(IF(N25="",P25/O25,P25/N25),"")) | T25: =IFERROR(IF(S25="","",S25/Q25*365/12),"") | U25: =IFERROR(IF(S25="","",S25/Q25*365),"")
H26: =IFERROR(__xludf.DUMMYFUNCTION("IF(F26="""","""",IFERROR(GOOGLEFINANCE(UPPER(F26),""price""),""""))"),"") | J26: =IF(OR(A26="",E26<>""),"",IFERROR(H26-I26,"")) | O26: =IF(A26="Buy",IF(L26="","",L26*K26*100),IF(A26="Assigned",IF(L26="","",L26*K26*100),IF(A26="Sell",IF(OR(I26="",K26=""),"",I26*K26*100),""))) | P26: =IF(M26="","",IF(A26="Sell",(L26-M26)*K26*100,IF(OR(A26="Buy",A26="Assigned"),(M26-L26)*K26*100,""))) | Q26: =IF(E26="","",IF(E26-C26<1,1,E26-C26)) | R26: =IFERROR(IF(P26="","",P26/Q26),"") | S26: =IF(E26="","",IFERROR(IF(N26="",P26/O26,P26/N26),"")) | T26: =IFERROR(IF(S26="","",S26/Q26*365/12),"") | U26: =IFERROR(IF(S26="","",S26/Q26*365),"")
H27: =IFERROR(__xludf.DUMMYFUNCTION("IF(F27="""","""",IFERROR(GOOGLEFINANCE(UPPER(F27),""price""),""""))"),"") | J27: =IF(OR(A27="",E27<>""),"",IFERROR(H27-I27,"")) | O27: =IF(A27="Buy",IF(L27="","",L27*K27*100),IF(A27="Assigned",IF(L27="","",L27*K27*100),IF(A27="Sell",IF(OR(I27="",K27=""),"",I27*K27*100),""))) | P27: =IF(M27="","",IF(A27="Sell",(L27-M27)*K27*100,IF(OR(A27="Buy",A27="Assigned"),(M27-L27)*K27*100,""))) | Q27: =IF(E27="","",IF(E27-C27<1,1,E27-C27)) | R27: =IFERROR(IF(P27="","",P27/Q27),"") | S27: =IF(E27="","",IFERROR(IF(N27="",P27/O27,P27/N27),"")) | T27: =IFERROR(IF(S27="","",S27/Q27*365/12),"") | U27: =IFERROR(IF(S27="","",S27/Q27*365),"")
H28: =IFERROR(__xludf.DUMMYFUNCTION("IF(F28="""","""",IFERROR(GOOGLEFINANCE(UPPER(F28),""price""),""""))"),"") | J28: =IF(OR(A28="",E28<>""),"",IFERROR(H28-I28,"")) | O28: =IF(A28="Buy",IF(L28="","",L28*K28*100),IF(A28="Assigned",IF(L28="","",L28*K28*100),IF(A28="Sell",IF(OR(I28="",K28=""),"",I28*K28*100),""))) | P28: =IF(M28="","",IF(A28="Sell",(L28-M28)*K28*100,IF(OR(A28="Buy",A28="Assigned"),(M28-L28)*K28*100,""))) | Q28: =IF(E28="","",IF(E28-C28<1,1,E28-C28)) | R28: =IFERROR(IF(P28="","",P28/Q28),"") | S28: =IF(E28="","",IFERROR(IF(N28="",P28/O28,P28/N28),"")) | T28: =IFERROR(IF(S28="","",S28/Q28*365/12),"") | U28: =IFERROR(IF(S28="","",S28/Q28*365),"")
H29: =IFERROR(__xludf.DUMMYFUNCTION("IF(F29="""","""",IFERROR(GOOGLEFINANCE(UPPER(F29),""price""),""""))"),"") | J29: =IF(OR(A29="",E29<>""),"",IFERROR(H29-I29,"")) | O29: =IF(A29="Buy",IF(L29="","",L29*K29*100),IF(A29="Assigned",IF(L29="","",L29*K29*100),IF(A29="Sell",IF(OR(I29="",K29=""),"",I29*K29*100),""))) | P29: =IF(M29="","",IF(A29="Sell",(L29-M29)*K29*100,IF(OR(A29="Buy",A29="Assigned"),(M29-L29)*K29*100,""))) | Q29: =IF(E29="","",IF(E29-C29<1,1,E29-C29)) | R29: =IFERROR(IF(P29="","",P29/Q29),"") | S29: =IF(E29="","",IFERROR(IF(N29="",P29/O29,P29/N29),"")) | T29: =IFERROR(IF(S29="","",S29/Q29*365/12),"") | U29: =IFERROR(IF(S29="","",S29/Q29*365),"")
H30: =IFERROR(__xludf.DUMMYFUNCTION("IF(F30="""","""",IFERROR(GOOGLEFINANCE(UPPER(F30),""price""),""""))"),"") | J30: =IF(OR(A30="",E30<>""),"",IFERROR(H30-I30,"")) | O30: =IF(A30="Buy",IF(L30="","",L30*K30*100),IF(A30="Assigned",IF(L30="","",L30*K30*100),IF(A30="Sell",IF(OR(I30="",K30=""),"",I30*K30*100),""))) | P30: =IF(M30="","",IF(A30="Sell",(L30-M30)*K30*100,IF(OR(A30="Buy",A30="Assigned"),(M30-L30)*K30*100,""))) | Q30: =IF(E30="","",IF(E30-C30<1,1,E30-C30)) | R30: =IFERROR(IF(P30="","",P30/Q30),"") | S30: =IF(E30="","",IFERROR(IF(N30="",P30/O30,P30/N30),"")) | T30: =IFERROR(IF(S30="","",S30/Q30*365/12),"") | U30: =IFERROR(IF(S30="","",S30/Q30*365),"")
H31: =IFERROR(__xludf.DUMMYFUNCTION("IF(F31="""","""",IFERROR(GOOGLEFINANCE(UPPER(F31),""price""),""""))"),"") | J31: =IF(OR(A31="",E31<>""),"",IFERROR(H31-I31,"")) | O31: =IF(A31="Buy",IF(L31="","",L31*K31*100),IF(A31="Assigned",IF(L31="","",L31*K31*100),IF(A31="Sell",IF(OR(I31="",K31=""),"",I31*K31*100),""))) | P31: =IF(M31="","",IF(A31="Sell",(L31-M31)*K31*100,IF(OR(A31="Buy",A31="Assigned"),(M31-L31)*K31*100,""))) | Q31: =IF(E31="","",IF(E31-C31<1,1,E31-C31)) | R31: =IFERROR(IF(P31="","",P31/Q31),"") | S31: =IF(E31="","",IFERROR(IF(N31="",P31/O31,P31/N31),"")) | T31: =IFERROR(IF(S31="","",S31/Q31*365/12),"") | U31: =IFERROR(IF(S31="","",S31/Q31*365),"")
H32: =IFERROR(__xludf.DUMMYFUNCTION("IF(F32="""","""",IFERROR(GOOGLEFINANCE(UPPER(F32),""price""),""""))"),"") | J32: =IF(OR(A32="",E32<>""),"",IFERROR(H32-I32,"")) | O32: =IF(A32="Buy",IF(L32="","",L32*K32*100),IF(A32="Assigned",IF(L32="","",L32*K32*100),IF(A32="Sell",IF(OR(I32="",K32=""),"",I32*K32*100),""))) | P32: =IF(M32="","",IF(A32="Sell",(L32-M32)*K32*100,IF(OR(A32="Buy",A32="Assigned"),(M32-L32)*K32*100,""))) | Q32: =IF(E32="","",IF(E32-C32<1,1,E32-C32)) | R32: =IFERROR(IF(P32="","",P32/Q32),"") | S32: =IF(E32="","",IFERROR(IF(N32="",P32/O32,P32/N32),"")) | T32: =IFERROR(IF(S32="","",S32/Q32*365/12),"") | U32: =IFERROR(IF(S32="","",S32/Q32*365),"")
H33: =IFERROR(__xludf.DUMMYFUNCTION("IF(F33="""","""",IFERROR(GOOGLEFINANCE(UPPER(F33),""price""),""""))"),"") | J33: =IF(OR(A33="",E33<>""),"",IFERROR(H33-I33,"")) | O33: =IF(A33="Buy",IF(L33="","",L33*K33*100),IF(A33="Assigned",IF(L33="","",L33*K33*100),IF(A33="Sell",IF(OR(I33="",K33=""),"",I33*K33*100),""))) | P33: =IF(M33="","",IF(A33="Sell",(L33-M33)*K33*100,IF(OR(A33="Buy",A33="Assigned"),(M33-L33)*K33*100,""))) | Q33: =IF(E33="","",IF(E33-C33<1,1,E33-C33)) | R33: =IFERROR(IF(P33="","",P33/Q33),"") | S33: =IF(E33="","",IFERROR(IF(N33="",P33/O33,P33/N33),"")) | T33: =IFERROR(IF(S33="","",S33/Q33*365/12),"") | U33: =IFERROR(IF(S33="","",S33/Q33*365),"")
H34: =IFERROR(__xludf.DUMMYFUNCTION("IF(F34="""","""",IFERROR(GOOGLEFINANCE(UPPER(F34),""price""),""""))"),"") | J34: =IF(OR(A34="",E34<>""),"",IFERROR(H34-I34,"")) | O34: =IF(A34="Buy",IF(L34="","",L34*K34*100),IF(A34="Assigned",IF(L34="","",L34*K34*100),IF(A34="Sell",IF(OR(I34="",K34=""),"",I34*K34*100),""))) | P34: =IF(M34="","",IF(A34="Sell",(L34-M34)*K34*100,IF(OR(A34="Buy",A34="Assigned"),(M34-L34)*K34*100,""))) | Q34: =IF(E34="","",IF(E34-C34<1,1,E34-C34)) | R34: =IFERROR(IF(P34="","",P34/Q34),"") | S34: =IF(E34="","",IFERROR(IF(N34="",P34/O34,P34/N34),"")) | T34: =IFERROR(IF(S34="","",S34/Q34*365/12),"") | U34: =IFERROR(IF(S34="","",S34/Q34*365),"")
H35: =IFERROR(__xludf.DUMMYFUNCTION("IF(F35="""","""",IFERROR(GOOGLEFINANCE(UPPER(F35),""price""),""""))"),"") | J35: =IF(OR(A35="",E35<>""),"",IFERROR(H35-I35,"")) | O35: =IF(A35="Buy",IF(L35="","",L35*K35*100),IF(A35="Assigned",IF(L35="","",L35*K35*100),IF(A35="Sell",IF(OR(I35="",K35=""),"",I35*K35*100),""))) | P35: =IF(M35="","",IF(A35="Sell",(L35-M35)*K35*100,IF(OR(A35="Buy",A35="Assigned"),(M35-L35)*K35*100,""))) | Q35: =IF(E35="","",IF(E35-C35<1,1,E35-C35)) | R35: =IFERROR(IF(P35="","",P35/Q35),"") | S35: =IF(E35="","",IFERROR(IF(N35="",P35/O35,P35/N35),"")) | T35: =IFERROR(IF(S35="","",S35/Q35*365/12),"") | U35: =IFERROR(IF(S35="","",S35/Q35*365),"")
H36: =IFERROR(__xludf.DUMMYFUNCTION("IF(F36="""","""",IFERROR(GOOGLEFINANCE(UPPER(F36),""price""),""""))"),"") | J36: =IF(OR(A36="",E36<>""),"",IFERROR(H36-I36,"")) | O36: =IF(A36="Buy",IF(L36="","",L36*K36*100),IF(A36="Assigned",IF(L36="","",L36*K36*100),IF(A36="Sell",IF(OR(I36="",K36=""),"",I36*K36*100),""))) | P36: =IF(M36="","",IF(A36="Sell",(L36-M36)*K36*100,IF(OR(A36="Buy",A36="Assigned"),(M36-L36)*K36*100,""))) | Q36: =IF(E36="","",IF(E36-C36<1,1,E36-C36)) | R36: =IFERROR(IF(P36="","",P36/Q36),"") | S36: =IF(E36="","",IFERROR(IF(N36="",P36/O36,P36/N36),"")) | T36: =IFERROR(IF(S36="","",S36/Q36*365/12),"") | U36: =IFERROR(IF(S36="","",S36/Q36*365),"")
H37: =IFERROR(__xludf.DUMMYFUNCTION("IF(F37="""","""",IFERROR(GOOGLEFINANCE(UPPER(F37),""price""),""""))"),"") | J37: =IF(OR(A37="",E37<>""),"",IFERROR(H37-I37,"")) | O37: =IF(A37="Buy",IF(L37="","",L37*K37*100),IF(A37="Assigned",IF(L37="","",L37*K37*100),IF(A37="Sell",IF(OR(I37="",K37=""),"",I37*K37*100),""))) | P37: =IF(M37="","",IF(A37="Sell",(L37-M37)*K37*100,IF(OR(A37="Buy",A37="Assigned"),(M37-L37)*K37*100,""))) | Q37: =IF(E37="","",IF(E37-C37<1,1,E37-C37)) | R37: =IFERROR(IF(P37="","",P37/Q37),"") | S37: =IF(E37="","",IFERROR(IF(N37="",P37/O37,P37/N37),"")) | T37: =IFERROR(IF(S37="","",S37/Q37*365/12),"") | U37: =IFERROR(IF(S37="","",S37/Q37*365),"")
H38: =IFERROR(__xludf.DUMMYFUNCTION("IF(F38="""","""",IFERROR(GOOGLEFINANCE(UPPER(F38),""price""),""""))"),"") | J38: =IF(OR(A38="",E38<>""),"",IFERROR(H38-I38,"")) | O38: =IF(A38="Buy",IF(L38="","",L38*K38*100),IF(A38="Assigned",IF(L38="","",L38*K38*100),IF(A38="Sell",IF(OR(I38="",K38=""),"",I38*K38*100),""))) | P38: =IF(M38="","",IF(A38="Sell",(L38-M38)*K38*100,IF(OR(A38="Buy",A38="Assigned"),(M38-L38)*K38*100,""))) | Q38: =IF(E38="","",IF(E38-C38<1,1,E38-C38)) | R38: =IFERROR(IF(P38="","",P38/Q38),"") | S38: =IF(E38="","",IFERROR(IF(N38="",P38/O38,P38/N38),"")) | T38: =IFERROR(IF(S38="","",S38/Q38*365/12),"") | U38: =IFERROR(IF(S38="","",S38/Q38*365),"")
